Winding down
Winding down
Winding down
Winding down
Winding down
Winding down
Winding down
  File "./run_sim_perflow_first_packet_slo_exponential_lognormal_different_means_scan_1_core.py", line 50
    "mean": 200.0.,
                  ^
SyntaxError: invalid syntax
Winding down
Winding down
Winding down
Winding down
Winding down
Winding down
Winding down
Winding down
Traceback (most recent call last):
  File "/armadillo/users/kkaffes/repos/sched_sim/src/scheduler/scheduler.py", line 177, in become_active
    total_time = self.env.now - request.start_time + request.exec_time
AttributeError: 'NoneType' object has no attribute 'start_time'

The above exception was the direct cause of the following exception:

Traceback (most recent call last):
  File "../../src/sim.py", line 140, in <module>
    main()
  File "../../src/sim.py", line 134, in main
    env.run(until=opts.sim_time)
  File "/armadillo/users/kkaffes/.local/lib/python2.7/site-packages/simpy/core.py", line 137, in run
    self.step()
  File "/armadillo/users/kkaffes/.local/lib/python2.7/site-packages/simpy/core.py", line 229, in step
    raise exc
AttributeError: 'NoneType' object has no attribute 'start_time'
Process Process-15:
Traceback (most recent call last):
  File "/usr/lib/python2.7/multiprocessing/process.py", line 258, in _bootstrap
    self.run()
  File "/usr/lib/python2.7/multiprocessing/process.py", line 114, in run
    self._target(*self._args, **self._kwargs)
  File "./run_sim_global_fcfs_exponential_exponential_different_means_scan_8_cores.py", line 135, in run_sim
    output = json.loads(out)
  File "/usr/lib/python2.7/json/__init__.py", line 338, in loads
    return _default_decoder.decode(s)
  File "/usr/lib/python2.7/json/decoder.py", line 366, in decode
    obj, end = self.raw_decode(s, idx=_w(s, 0).end())
  File "/usr/lib/python2.7/json/decoder.py", line 384, in raw_decode
    raise ValueError("No JSON object could be decoded")
ValueError: No JSON object could be decoded
close failed in file object destructor:
sys.excepthook is missing
lost sys.stderr
close failed in file object destructor:
sys.excepthook is missing
lost sys.stderr
Winding down
Traceback (most recent call last):
  File "/armadillo/users/kkaffes/repos/sched_sim/src/scheduler/scheduler.py", line 177, in become_active
    total_time = self.env.now - request.start_time + request.exec_time
AttributeError: 'NoneType' object has no attribute 'start_time'

The above exception was the direct cause of the following exception:

Traceback (most recent call last):
  File "../../src/sim.py", line 140, in <module>
    main()
  File "../../src/sim.py", line 134, in main
    env.run(until=opts.sim_time)
  File "/armadillo/users/kkaffes/.local/lib/python2.7/site-packages/simpy/core.py", line 137, in run
    self.step()
  File "/armadillo/users/kkaffes/.local/lib/python2.7/site-packages/simpy/core.py", line 229, in step
    raise exc
AttributeError: 'NoneType' object has no attribute 'start_time'
Traceback (most recent call last):
  File "/armadillo/users/kkaffes/repos/sched_sim/src/scheduler/scheduler.py", line 177, in become_active
    total_time = self.env.now - request.start_time + request.exec_time
AttributeError: 'NoneType' object has no attribute 'start_time'

The above exception was the direct cause of the following exception:

Traceback (most recent call last):
  File "../../src/sim.py", line 140, in <module>
    main()
  File "../../src/sim.py", line 134, in main
    env.run(until=opts.sim_time)
  File "/armadillo/users/kkaffes/.local/lib/python2.7/site-packages/simpy/core.py", line 137, in run
    self.step()
  File "/armadillo/users/kkaffes/.local/lib/python2.7/site-packages/simpy/core.py", line 229, in step
    raise exc
AttributeError: 'NoneType' object has no attribute 'start_time'
Traceback (most recent call last):
  File "/armadillo/users/kkaffes/repos/sched_sim/src/scheduler/scheduler.py", line 177, in become_active
    total_time = self.env.now - request.start_time + request.exec_time
AttributeError: 'NoneType' object has no attribute 'start_time'

The above exception was the direct cause of the following exception:

Traceback (most recent call last):
  File "../../src/sim.py", line 140, in <module>
    main()
  File "../../src/sim.py", line 134, in main
    env.run(until=opts.sim_time)
  File "/armadillo/users/kkaffes/.local/lib/python2.7/site-packages/simpy/core.py", line 137, in run
    self.step()
  File "/armadillo/users/kkaffes/.local/lib/python2.7/site-packages/simpy/core.py", line 229, in step
    raise exc
AttributeError: 'NoneType' object has no attribute 'start_time'
Process Process-15:
Traceback (most recent call last):
  File "/usr/lib/python2.7/multiprocessing/process.py", line 258, in _bootstrap
    self.run()
  File "/usr/lib/python2.7/multiprocessing/process.py", line 114, in run
    self._target(*self._args, **self._kwargs)
  File "./run_sim_perflow_first_packet_wait_exponential_exponential_different_means_scan_8_cores.py", line 137, in run_sim
    output = json.loads(out)
  File "/usr/lib/python2.7/json/__init__.py", line 338, in loads
    return _default_decoder.decode(s)
  File "/usr/lib/python2.7/json/decoder.py", line 366, in decode
    obj, end = self.raw_decode(s, idx=_w(s, 0).end())
  File "/usr/lib/python2.7/json/decoder.py", line 384, in raw_decode
    raise ValueError("No JSON object could be decoded")
ValueError: No JSON object could be decoded
Process Process-15:
Traceback (most recent call last):
  File "/usr/lib/python2.7/multiprocessing/process.py", line 258, in _bootstrap
    self.run()
  File "/usr/lib/python2.7/multiprocessing/process.py", line 114, in run
    self._target(*self._args, **self._kwargs)
  File "./run_sim_perflow_first_packet_slo_exponential_exponential_different_means_scan_8_cores.py", line 137, in run_sim
    output = json.loads(out)
  File "/usr/lib/python2.7/json/__init__.py", line 338, in loads
    return _default_decoder.decode(s)
  File "/usr/lib/python2.7/json/decoder.py", line 366, in decode
    obj, end = self.raw_decode(s, idx=_w(s, 0).end())
  File "/usr/lib/python2.7/json/decoder.py", line 384, in raw_decode
    raise ValueError("No JSON object could be decoded")
ValueError: No JSON object could be decoded
close failed in file object destructor:
sys.excepthook is missing
lost sys.stderr
close failed in file object destructor:
sys.excepthook is missing
lost sys.stderr
close failed in file object destructor:
sys.excepthook is missing
lost sys.stderr
Process Process-15:
Traceback (most recent call last):
  File "/usr/lib/python2.7/multiprocessing/process.py", line 258, in _bootstrap
    self.run()
  File "/usr/lib/python2.7/multiprocessing/process.py", line 114, in run
    self._target(*self._args, **self._kwargs)
  File "./run_sim_perflow_longest_load_exponential_exponential_different_means_scan_8_cores.py", line 137, in run_sim
    output = json.loads(out)
  File "/usr/lib/python2.7/json/__init__.py", line 339, in loads
    return _default_decoder.decode(s)
  File "/usr/lib/python2.7/json/decoder.py", line 364, in decode
    obj, end = self.raw_decode(s, idx=_w(s, 0).end())
  File "/usr/lib/python2.7/json/decoder.py", line 382, in raw_decode
    raise ValueError("No JSON object could be decoded")
ValueError: No JSON object could be decoded
Winding down
Winding down
Winding down
Process Process-1:
Traceback (most recent call last):
  File "/usr/lib/python2.7/multiprocessing/process.py", line 258, in _bootstrap
    self.run()
  File "/usr/lib/python2.7/multiprocessing/process.py", line 114, in run
    self._target(*self._args, **self._kwargs)
  File "./run_sim_global_fcfs_exponential_lognormal_exponential_scan_8_cores.py", line 181, in run_sim
    with open(flow_name, 'w') as f:
IOError: [Errno 36] File name too long: '../../out/fall2017/global_queue_fcfs_exponential_lognormal_exponential_scan/sim_8_global_0.0_global_flow0_exponential_request_poisson_arrival_0.0166666666667_2.0_0.0_enqfrontFalse_flow1_lognormal_request_poisson_arrival_0.0166666666667_20.0_200.0_0.0_enqfrontFalse_flow2_exponential_request_poisson_arrival_0.0166666666667_20.0_0.0_enqfrontFalse_flow0'
Process Process-2:
Traceback (most recent call last):
  File "/usr/lib/python2.7/multiprocessing/process.py", line 258, in _bootstrap
    self.run()
  File "/usr/lib/python2.7/multiprocessing/process.py", line 114, in run
    self._target(*self._args, **self._kwargs)
  File "./run_sim_global_fcfs_exponential_lognormal_exponential_scan_8_cores.py", line 181, in run_sim
    with open(flow_name, 'w') as f:
IOError: [Errno 36] File name too long: '../../out/fall2017/global_queue_fcfs_exponential_lognormal_exponential_scan/sim_8_global_0.0_global_flow0_exponential_request_poisson_arrival_0.0333333333333_2.0_0.0_enqfrontFalse_flow1_lognormal_request_poisson_arrival_0.0333333333333_20.0_200.0_0.0_enqfrontFalse_flow2_exponential_request_poisson_arrival_0.0333333333333_20.0_0.0_enqfrontFalse_flow0'
Process Process-3:
Traceback (most recent call last):
  File "/usr/lib/python2.7/multiprocessing/process.py", line 258, in _bootstrap
    self.run()
  File "/usr/lib/python2.7/multiprocessing/process.py", line 114, in run
    self._target(*self._args, **self._kwargs)
  File "./run_sim_global_fcfs_exponential_lognormal_exponential_scan_8_cores.py", line 197, in run_sim
    with open(flow_name, 'w') as f:
IOError: [Errno 36] File name too long: '../../out/fall2017/global_queue_fcfs_exponential_lognormal_exponential_scan/sim_8_global_0.0_global_flow0_exponential_request_poisson_arrival_0.05_2.0_0.0_enqfrontFalse_flow1_lognormal_request_poisson_arrival_0.05_20.0_200.0_0.0_enqfrontFalse_flow2_exponential_request_poisson_arrival_0.05_20.0_0.0_enqfrontFalse_flow0.throughput.total'
Process Process-1:
Traceback (most recent call last):
  File "/usr/lib/python2.7/multiprocessing/process.py", line 258, in _bootstrap
    self.run()
  File "/usr/lib/python2.7/multiprocessing/process.py", line 114, in run
    self._target(*self._args, **self._kwargs)
  File "./run_sim_perflow_first_packet_slo_exponential_lognormal_exponential_scan_8_cores.py", line 184, in run_sim
    with open(flow_name, 'w') as f:
IOError: [Errno 36] File name too long: '../../out/fall2017/perflow_queue_first_packet_slo_exponential_lognormal_exponential_scan/sim_8_perflow_0.0_FirstPacketLatencyDequeuePolicy_flow0_exponential_request_poisson_arrival_0.0166666666667_2.0_2.0_enqfrontTrue_flow1_lognormal_request_poisson_arrival_0.0166666666667_20.0_200.0_2.0_enqfrontFalse_flow2_exponential_request_poisson_arrival_0.0166666666667_20.0_2.0_enqfrontTrue_flow0'
Process Process-4:
Traceback (most recent call last):
  File "/usr/lib/python2.7/multiprocessing/process.py", line 258, in _bootstrap
    self.run()
  File "/usr/lib/python2.7/multiprocessing/process.py", line 114, in run
    self._target(*self._args, **self._kwargs)
  File "./run_sim_global_fcfs_exponential_lognormal_exponential_scan_8_cores.py", line 181, in run_sim
    with open(flow_name, 'w') as f:
IOError: [Errno 36] File name too long: '../../out/fall2017/global_queue_fcfs_exponential_lognormal_exponential_scan/sim_8_global_0.0_global_flow0_exponential_request_poisson_arrival_0.0666666666667_2.0_0.0_enqfrontFalse_flow1_lognormal_request_poisson_arrival_0.0666666666667_20.0_200.0_0.0_enqfrontFalse_flow2_exponential_request_poisson_arrival_0.0666666666667_20.0_0.0_enqfrontFalse_flow0'
Process Process-1:
Traceback (most recent call last):
  File "/usr/lib/python2.7/multiprocessing/process.py", line 258, in _bootstrap
    self.run()
  File "/usr/lib/python2.7/multiprocessing/process.py", line 114, in run
    self._target(*self._args, **self._kwargs)
  File "./run_sim_perflow_first_packet_wait_exponential_lognormal_exponential_scan_8_cores.py", line 184, in run_sim
    with open(flow_name, 'w') as f:
IOError: [Errno 36] File name too long: '../../out/fall2017/perflow_queue_first_packet_wait_exponential_lognormal_exponential_scan/sim_8_perflow_0.0_FirstPacketWaitDequeuePolicy_flow0_exponential_request_poisson_arrival_0.0166666666667_2.0_2.0_enqfrontTrue_flow1_lognormal_request_poisson_arrival_0.0166666666667_20.0_200.0_2.0_enqfrontFalse_flow2_exponential_request_poisson_arrival_0.0166666666667_20.0_2.0_enqfrontTrue_flow0'
Process Process-5:
Traceback (most recent call last):
  File "/usr/lib/python2.7/multiprocessing/process.py", line 258, in _bootstrap
    self.run()
  File "/usr/lib/python2.7/multiprocessing/process.py", line 114, in run
    self._target(*self._args, **self._kwargs)
  File "./run_sim_global_fcfs_exponential_lognormal_exponential_scan_8_cores.py", line 181, in run_sim
    with open(flow_name, 'w') as f:
IOError: [Errno 36] File name too long: '../../out/fall2017/global_queue_fcfs_exponential_lognormal_exponential_scan/sim_8_global_0.0_global_flow0_exponential_request_poisson_arrival_0.0833333333333_2.0_0.0_enqfrontFalse_flow1_lognormal_request_poisson_arrival_0.0833333333333_20.0_200.0_0.0_enqfrontFalse_flow2_exponential_request_poisson_arrival_0.0833333333333_20.0_0.0_enqfrontFalse_flow0'
Process Process-1:
Traceback (most recent call last):
  File "/usr/lib/python2.7/multiprocessing/process.py", line 258, in _bootstrap
    self.run()
  File "/usr/lib/python2.7/multiprocessing/process.py", line 114, in run
    self._target(*self._args, **self._kwargs)
  File "./run_sim_perflow_longest_load_exponential_lognormal_exponential_scan_8_cores.py", line 184, in run_sim
    with open(flow_name, 'w') as f:
IOError: [Errno 36] File name too long: '../../out/fall2017/perflow_queue_longest_load_exponential_lognormal_exponential_scan/sim_8_perflow_0.0_LongestLoadDequeuePolicy_flow0_exponential_request_poisson_arrival_0.0166666666667_2.0_2.0_enqfrontTrue_flow1_lognormal_request_poisson_arrival_0.0166666666667_20.0_200.0_2.0_enqfrontFalse_flow2_exponential_request_poisson_arrival_0.0166666666667_20.0_2.0_enqfrontTrue_flow0'
Process Process-6:
Traceback (most recent call last):
  File "/usr/lib/python2.7/multiprocessing/process.py", line 258, in _bootstrap
    self.run()
  File "/usr/lib/python2.7/multiprocessing/process.py", line 114, in run
    self._target(*self._args, **self._kwargs)
  File "./run_sim_global_fcfs_exponential_lognormal_exponential_scan_8_cores.py", line 197, in run_sim
    with open(flow_name, 'w') as f:
IOError: [Errno 36] File name too long: '../../out/fall2017/global_queue_fcfs_exponential_lognormal_exponential_scan/sim_8_global_0.0_global_flow0_exponential_request_poisson_arrival_0.1_2.0_0.0_enqfrontFalse_flow1_lognormal_request_poisson_arrival_0.1_20.0_200.0_0.0_enqfrontFalse_flow2_exponential_request_poisson_arrival_0.1_20.0_0.0_enqfrontFalse_flow0.throughput.total'
Process Process-2:
Traceback (most recent call last):
  File "/usr/lib/python2.7/multiprocessing/process.py", line 258, in _bootstrap
    self.run()
  File "/usr/lib/python2.7/multiprocessing/process.py", line 114, in run
    self._target(*self._args, **self._kwargs)
  File "./run_sim_perflow_first_packet_slo_exponential_lognormal_exponential_scan_8_cores.py", line 184, in run_sim
    with open(flow_name, 'w') as f:
IOError: [Errno 36] File name too long: '../../out/fall2017/perflow_queue_first_packet_slo_exponential_lognormal_exponential_scan/sim_8_perflow_0.0_FirstPacketLatencyDequeuePolicy_flow0_exponential_request_poisson_arrival_0.0333333333333_2.0_2.0_enqfrontTrue_flow1_lognormal_request_poisson_arrival_0.0333333333333_20.0_200.0_2.0_enqfrontFalse_flow2_exponential_request_poisson_arrival_0.0333333333333_20.0_2.0_enqfrontTrue_flow0'
Process Process-2:
Traceback (most recent call last):
  File "/usr/lib/python2.7/multiprocessing/process.py", line 258, in _bootstrap
    self.run()
  File "/usr/lib/python2.7/multiprocessing/process.py", line 114, in run
    self._target(*self._args, **self._kwargs)
  File "./run_sim_perflow_first_packet_wait_exponential_lognormal_exponential_scan_8_cores.py", line 184, in run_sim
    with open(flow_name, 'w') as f:
IOError: [Errno 36] File name too long: '../../out/fall2017/perflow_queue_first_packet_wait_exponential_lognormal_exponential_scan/sim_8_perflow_0.0_FirstPacketWaitDequeuePolicy_flow0_exponential_request_poisson_arrival_0.0333333333333_2.0_2.0_enqfrontTrue_flow1_lognormal_request_poisson_arrival_0.0333333333333_20.0_200.0_2.0_enqfrontFalse_flow2_exponential_request_poisson_arrival_0.0333333333333_20.0_2.0_enqfrontTrue_flow0'
Process Process-7:
Traceback (most recent call last):
  File "/usr/lib/python2.7/multiprocessing/process.py", line 258, in _bootstrap
    self.run()
  File "/usr/lib/python2.7/multiprocessing/process.py", line 114, in run
    self._target(*self._args, **self._kwargs)
  File "./run_sim_global_fcfs_exponential_lognormal_exponential_scan_8_cores.py", line 181, in run_sim
    with open(flow_name, 'w') as f:
IOError: [Errno 36] File name too long: '../../out/fall2017/global_queue_fcfs_exponential_lognormal_exponential_scan/sim_8_global_0.0_global_flow0_exponential_request_poisson_arrival_0.116666666667_2.0_0.0_enqfrontFalse_flow1_lognormal_request_poisson_arrival_0.116666666667_20.0_200.0_0.0_enqfrontFalse_flow2_exponential_request_poisson_arrival_0.116666666667_20.0_0.0_enqfrontFalse_flow0'
Process Process-2:
Traceback (most recent call last):
  File "/usr/lib/python2.7/multiprocessing/process.py", line 258, in _bootstrap
    self.run()
  File "/usr/lib/python2.7/multiprocessing/process.py", line 114, in run
    self._target(*self._args, **self._kwargs)
  File "./run_sim_perflow_longest_load_exponential_lognormal_exponential_scan_8_cores.py", line 184, in run_sim
    with open(flow_name, 'w') as f:
IOError: [Errno 36] File name too long: '../../out/fall2017/perflow_queue_longest_load_exponential_lognormal_exponential_scan/sim_8_perflow_0.0_LongestLoadDequeuePolicy_flow0_exponential_request_poisson_arrival_0.0333333333333_2.0_2.0_enqfrontTrue_flow1_lognormal_request_poisson_arrival_0.0333333333333_20.0_200.0_2.0_enqfrontFalse_flow2_exponential_request_poisson_arrival_0.0333333333333_20.0_2.0_enqfrontTrue_flow0'
Process Process-3:
Traceback (most recent call last):
  File "/usr/lib/python2.7/multiprocessing/process.py", line 258, in _bootstrap
    self.run()
  File "/usr/lib/python2.7/multiprocessing/process.py", line 114, in run
    self._target(*self._args, **self._kwargs)
  File "./run_sim_perflow_first_packet_slo_exponential_lognormal_exponential_scan_8_cores.py", line 184, in run_sim
    with open(flow_name, 'w') as f:
IOError: [Errno 36] File name too long: '../../out/fall2017/perflow_queue_first_packet_slo_exponential_lognormal_exponential_scan/sim_8_perflow_0.0_FirstPacketLatencyDequeuePolicy_flow0_exponential_request_poisson_arrival_0.05_2.0_2.0_enqfrontTrue_flow1_lognormal_request_poisson_arrival_0.05_20.0_200.0_2.0_enqfrontFalse_flow2_exponential_request_poisson_arrival_0.05_20.0_2.0_enqfrontTrue_flow0'
Process Process-3:
Traceback (most recent call last):
  File "/usr/lib/python2.7/multiprocessing/process.py", line 258, in _bootstrap
    self.run()
  File "/usr/lib/python2.7/multiprocessing/process.py", line 114, in run
    self._target(*self._args, **self._kwargs)
  File "./run_sim_perflow_first_packet_wait_exponential_lognormal_exponential_scan_8_cores.py", line 184, in run_sim
    with open(flow_name, 'w') as f:
IOError: [Errno 36] File name too long: '../../out/fall2017/perflow_queue_first_packet_wait_exponential_lognormal_exponential_scan/sim_8_perflow_0.0_FirstPacketWaitDequeuePolicy_flow0_exponential_request_poisson_arrival_0.05_2.0_2.0_enqfrontTrue_flow1_lognormal_request_poisson_arrival_0.05_20.0_200.0_2.0_enqfrontFalse_flow2_exponential_request_poisson_arrival_0.05_20.0_2.0_enqfrontTrue_flow0'
Process Process-8:
Traceback (most recent call last):
  File "/usr/lib/python2.7/multiprocessing/process.py", line 258, in _bootstrap
    self.run()
  File "/usr/lib/python2.7/multiprocessing/process.py", line 114, in run
    self._target(*self._args, **self._kwargs)
  File "./run_sim_global_fcfs_exponential_lognormal_exponential_scan_8_cores.py", line 181, in run_sim
    with open(flow_name, 'w') as f:
IOError: [Errno 36] File name too long: '../../out/fall2017/global_queue_fcfs_exponential_lognormal_exponential_scan/sim_8_global_0.0_global_flow0_exponential_request_poisson_arrival_0.133333333333_2.0_0.0_enqfrontFalse_flow1_lognormal_request_poisson_arrival_0.133333333333_20.0_200.0_0.0_enqfrontFalse_flow2_exponential_request_poisson_arrival_0.133333333333_20.0_0.0_enqfrontFalse_flow0'
Process Process-3:
Traceback (most recent call last):
  File "/usr/lib/python2.7/multiprocessing/process.py", line 258, in _bootstrap
    self.run()
  File "/usr/lib/python2.7/multiprocessing/process.py", line 114, in run
    self._target(*self._args, **self._kwargs)
  File "./run_sim_perflow_longest_load_exponential_lognormal_exponential_scan_8_cores.py", line 184, in run_sim
    with open(flow_name, 'w') as f:
IOError: [Errno 36] File name too long: '../../out/fall2017/perflow_queue_longest_load_exponential_lognormal_exponential_scan/sim_8_perflow_0.0_LongestLoadDequeuePolicy_flow0_exponential_request_poisson_arrival_0.05_2.0_2.0_enqfrontTrue_flow1_lognormal_request_poisson_arrival_0.05_20.0_200.0_2.0_enqfrontFalse_flow2_exponential_request_poisson_arrival_0.05_20.0_2.0_enqfrontTrue_flow0'
Process Process-4:
Traceback (most recent call last):
  File "/usr/lib/python2.7/multiprocessing/process.py", line 258, in _bootstrap
    self.run()
  File "/usr/lib/python2.7/multiprocessing/process.py", line 114, in run
    self._target(*self._args, **self._kwargs)
  File "./run_sim_perflow_first_packet_slo_exponential_lognormal_exponential_scan_8_cores.py", line 184, in run_sim
    with open(flow_name, 'w') as f:
IOError: [Errno 36] File name too long: '../../out/fall2017/perflow_queue_first_packet_slo_exponential_lognormal_exponential_scan/sim_8_perflow_0.0_FirstPacketLatencyDequeuePolicy_flow0_exponential_request_poisson_arrival_0.0666666666667_2.0_2.0_enqfrontTrue_flow1_lognormal_request_poisson_arrival_0.0666666666667_20.0_200.0_2.0_enqfrontFalse_flow2_exponential_request_poisson_arrival_0.0666666666667_20.0_2.0_enqfrontTrue_flow0'
Process Process-9:
Traceback (most recent call last):
  File "/usr/lib/python2.7/multiprocessing/process.py", line 258, in _bootstrap
    self.run()
  File "/usr/lib/python2.7/multiprocessing/process.py", line 114, in run
    self._target(*self._args, **self._kwargs)
  File "./run_sim_global_fcfs_exponential_lognormal_exponential_scan_8_cores.py", line 197, in run_sim
    with open(flow_name, 'w') as f:
IOError: [Errno 36] File name too long: '../../out/fall2017/global_queue_fcfs_exponential_lognormal_exponential_scan/sim_8_global_0.0_global_flow0_exponential_request_poisson_arrival_0.15_2.0_0.0_enqfrontFalse_flow1_lognormal_request_poisson_arrival_0.15_20.0_200.0_0.0_enqfrontFalse_flow2_exponential_request_poisson_arrival_0.15_20.0_0.0_enqfrontFalse_flow0.throughput.total'
Process Process-4:
Traceback (most recent call last):
  File "/usr/lib/python2.7/multiprocessing/process.py", line 258, in _bootstrap
    self.run()
  File "/usr/lib/python2.7/multiprocessing/process.py", line 114, in run
    self._target(*self._args, **self._kwargs)
  File "./run_sim_perflow_first_packet_wait_exponential_lognormal_exponential_scan_8_cores.py", line 184, in run_sim
    with open(flow_name, 'w') as f:
IOError: [Errno 36] File name too long: '../../out/fall2017/perflow_queue_first_packet_wait_exponential_lognormal_exponential_scan/sim_8_perflow_0.0_FirstPacketWaitDequeuePolicy_flow0_exponential_request_poisson_arrival_0.0666666666667_2.0_2.0_enqfrontTrue_flow1_lognormal_request_poisson_arrival_0.0666666666667_20.0_200.0_2.0_enqfrontFalse_flow2_exponential_request_poisson_arrival_0.0666666666667_20.0_2.0_enqfrontTrue_flow0'
Process Process-4:
Traceback (most recent call last):
  File "/usr/lib/python2.7/multiprocessing/process.py", line 258, in _bootstrap
    self.run()
  File "/usr/lib/python2.7/multiprocessing/process.py", line 114, in run
    self._target(*self._args, **self._kwargs)
  File "./run_sim_perflow_longest_load_exponential_lognormal_exponential_scan_8_cores.py", line 184, in run_sim
    with open(flow_name, 'w') as f:
IOError: [Errno 36] File name too long: '../../out/fall2017/perflow_queue_longest_load_exponential_lognormal_exponential_scan/sim_8_perflow_0.0_LongestLoadDequeuePolicy_flow0_exponential_request_poisson_arrival_0.0666666666667_2.0_2.0_enqfrontTrue_flow1_lognormal_request_poisson_arrival_0.0666666666667_20.0_200.0_2.0_enqfrontFalse_flow2_exponential_request_poisson_arrival_0.0666666666667_20.0_2.0_enqfrontTrue_flow0'
Process Process-5:
Traceback (most recent call last):
  File "/usr/lib/python2.7/multiprocessing/process.py", line 258, in _bootstrap
    self.run()
  File "/usr/lib/python2.7/multiprocessing/process.py", line 114, in run
    self._target(*self._args, **self._kwargs)
  File "./run_sim_perflow_first_packet_slo_exponential_lognormal_exponential_scan_8_cores.py", line 184, in run_sim
    with open(flow_name, 'w') as f:
IOError: [Errno 36] File name too long: '../../out/fall2017/perflow_queue_first_packet_slo_exponential_lognormal_exponential_scan/sim_8_perflow_0.0_FirstPacketLatencyDequeuePolicy_flow0_exponential_request_poisson_arrival_0.0833333333333_2.0_2.0_enqfrontTrue_flow1_lognormal_request_poisson_arrival_0.0833333333333_20.0_200.0_2.0_enqfrontFalse_flow2_exponential_request_poisson_arrival_0.0833333333333_20.0_2.0_enqfrontTrue_flow0'
Process Process-10:
Traceback (most recent call last):
  File "/usr/lib/python2.7/multiprocessing/process.py", line 258, in _bootstrap
    self.run()
  File "/usr/lib/python2.7/multiprocessing/process.py", line 114, in run
    self._target(*self._args, **self._kwargs)
  File "./run_sim_global_fcfs_exponential_lognormal_exponential_scan_8_cores.py", line 181, in run_sim
    with open(flow_name, 'w') as f:
IOError: [Errno 36] File name too long: '../../out/fall2017/global_queue_fcfs_exponential_lognormal_exponential_scan/sim_8_global_0.0_global_flow0_exponential_request_poisson_arrival_0.166666666667_2.0_0.0_enqfrontFalse_flow1_lognormal_request_poisson_arrival_0.166666666667_20.0_200.0_0.0_enqfrontFalse_flow2_exponential_request_poisson_arrival_0.166666666667_20.0_0.0_enqfrontFalse_flow0'
Process Process-5:
Traceback (most recent call last):
  File "/usr/lib/python2.7/multiprocessing/process.py", line 258, in _bootstrap
    self.run()
  File "/usr/lib/python2.7/multiprocessing/process.py", line 114, in run
    self._target(*self._args, **self._kwargs)
  File "./run_sim_perflow_first_packet_wait_exponential_lognormal_exponential_scan_8_cores.py", line 184, in run_sim
    with open(flow_name, 'w') as f:
IOError: [Errno 36] File name too long: '../../out/fall2017/perflow_queue_first_packet_wait_exponential_lognormal_exponential_scan/sim_8_perflow_0.0_FirstPacketWaitDequeuePolicy_flow0_exponential_request_poisson_arrival_0.0833333333333_2.0_2.0_enqfrontTrue_flow1_lognormal_request_poisson_arrival_0.0833333333333_20.0_200.0_2.0_enqfrontFalse_flow2_exponential_request_poisson_arrival_0.0833333333333_20.0_2.0_enqfrontTrue_flow0'
Process Process-11:
Traceback (most recent call last):
  File "/usr/lib/python2.7/multiprocessing/process.py", line 258, in _bootstrap
    self.run()
  File "/usr/lib/python2.7/multiprocessing/process.py", line 114, in run
    self._target(*self._args, **self._kwargs)
  File "./run_sim_global_fcfs_exponential_lognormal_exponential_scan_8_cores.py", line 181, in run_sim
    with open(flow_name, 'w') as f:
IOError: [Errno 36] File name too long: '../../out/fall2017/global_queue_fcfs_exponential_lognormal_exponential_scan/sim_8_global_0.0_global_flow0_exponential_request_poisson_arrival_0.183333333333_2.0_0.0_enqfrontFalse_flow1_lognormal_request_poisson_arrival_0.183333333333_20.0_200.0_0.0_enqfrontFalse_flow2_exponential_request_poisson_arrival_0.183333333333_20.0_0.0_enqfrontFalse_flow0'
Process Process-5:
Traceback (most recent call last):
  File "/usr/lib/python2.7/multiprocessing/process.py", line 258, in _bootstrap
    self.run()
  File "/usr/lib/python2.7/multiprocessing/process.py", line 114, in run
    self._target(*self._args, **self._kwargs)
  File "./run_sim_perflow_longest_load_exponential_lognormal_exponential_scan_8_cores.py", line 184, in run_sim
    with open(flow_name, 'w') as f:
IOError: [Errno 36] File name too long: '../../out/fall2017/perflow_queue_longest_load_exponential_lognormal_exponential_scan/sim_8_perflow_0.0_LongestLoadDequeuePolicy_flow0_exponential_request_poisson_arrival_0.0833333333333_2.0_2.0_enqfrontTrue_flow1_lognormal_request_poisson_arrival_0.0833333333333_20.0_200.0_2.0_enqfrontFalse_flow2_exponential_request_poisson_arrival_0.0833333333333_20.0_2.0_enqfrontTrue_flow0'
Process Process-6:
Traceback (most recent call last):
  File "/usr/lib/python2.7/multiprocessing/process.py", line 258, in _bootstrap
    self.run()
  File "/usr/lib/python2.7/multiprocessing/process.py", line 114, in run
    self._target(*self._args, **self._kwargs)
  File "./run_sim_perflow_first_packet_slo_exponential_lognormal_exponential_scan_8_cores.py", line 184, in run_sim
    with open(flow_name, 'w') as f:
IOError: [Errno 36] File name too long: '../../out/fall2017/perflow_queue_first_packet_slo_exponential_lognormal_exponential_scan/sim_8_perflow_0.0_FirstPacketLatencyDequeuePolicy_flow0_exponential_request_poisson_arrival_0.1_2.0_2.0_enqfrontTrue_flow1_lognormal_request_poisson_arrival_0.1_20.0_200.0_2.0_enqfrontFalse_flow2_exponential_request_poisson_arrival_0.1_20.0_2.0_enqfrontTrue_flow0'
Process Process-6:
Traceback (most recent call last):
  File "/usr/lib/python2.7/multiprocessing/process.py", line 258, in _bootstrap
    self.run()
  File "/usr/lib/python2.7/multiprocessing/process.py", line 114, in run
    self._target(*self._args, **self._kwargs)
  File "./run_sim_perflow_first_packet_wait_exponential_lognormal_exponential_scan_8_cores.py", line 184, in run_sim
    with open(flow_name, 'w') as f:
IOError: [Errno 36] File name too long: '../../out/fall2017/perflow_queue_first_packet_wait_exponential_lognormal_exponential_scan/sim_8_perflow_0.0_FirstPacketWaitDequeuePolicy_flow0_exponential_request_poisson_arrival_0.1_2.0_2.0_enqfrontTrue_flow1_lognormal_request_poisson_arrival_0.1_20.0_200.0_2.0_enqfrontFalse_flow2_exponential_request_poisson_arrival_0.1_20.0_2.0_enqfrontTrue_flow0'
Process Process-12:
Traceback (most recent call last):
  File "/usr/lib/python2.7/multiprocessing/process.py", line 258, in _bootstrap
    self.run()
  File "/usr/lib/python2.7/multiprocessing/process.py", line 114, in run
    self._target(*self._args, **self._kwargs)
  File "./run_sim_global_fcfs_exponential_lognormal_exponential_scan_8_cores.py", line 197, in run_sim
    with open(flow_name, 'w') as f:
IOError: [Errno 36] File name too long: '../../out/fall2017/global_queue_fcfs_exponential_lognormal_exponential_scan/sim_8_global_0.0_global_flow0_exponential_request_poisson_arrival_0.2_2.0_0.0_enqfrontFalse_flow1_lognormal_request_poisson_arrival_0.2_20.0_200.0_0.0_enqfrontFalse_flow2_exponential_request_poisson_arrival_0.2_20.0_0.0_enqfrontFalse_flow0.throughput.total'
Process Process-6:
Traceback (most recent call last):
  File "/usr/lib/python2.7/multiprocessing/process.py", line 258, in _bootstrap
    self.run()
  File "/usr/lib/python2.7/multiprocessing/process.py", line 114, in run
    self._target(*self._args, **self._kwargs)
  File "./run_sim_perflow_longest_load_exponential_lognormal_exponential_scan_8_cores.py", line 184, in run_sim
    with open(flow_name, 'w') as f:
IOError: [Errno 36] File name too long: '../../out/fall2017/perflow_queue_longest_load_exponential_lognormal_exponential_scan/sim_8_perflow_0.0_LongestLoadDequeuePolicy_flow0_exponential_request_poisson_arrival_0.1_2.0_2.0_enqfrontTrue_flow1_lognormal_request_poisson_arrival_0.1_20.0_200.0_2.0_enqfrontFalse_flow2_exponential_request_poisson_arrival_0.1_20.0_2.0_enqfrontTrue_flow0'
Process Process-7:
Traceback (most recent call last):
  File "/usr/lib/python2.7/multiprocessing/process.py", line 258, in _bootstrap
    self.run()
  File "/usr/lib/python2.7/multiprocessing/process.py", line 114, in run
    self._target(*self._args, **self._kwargs)
  File "./run_sim_perflow_first_packet_slo_exponential_lognormal_exponential_scan_8_cores.py", line 184, in run_sim
    with open(flow_name, 'w') as f:
IOError: [Errno 36] File name too long: '../../out/fall2017/perflow_queue_first_packet_slo_exponential_lognormal_exponential_scan/sim_8_perflow_0.0_FirstPacketLatencyDequeuePolicy_flow0_exponential_request_poisson_arrival_0.116666666667_2.0_2.0_enqfrontTrue_flow1_lognormal_request_poisson_arrival_0.116666666667_20.0_200.0_2.0_enqfrontFalse_flow2_exponential_request_poisson_arrival_0.116666666667_20.0_2.0_enqfrontTrue_flow0'
Process Process-13:
Traceback (most recent call last):
  File "/usr/lib/python2.7/multiprocessing/process.py", line 258, in _bootstrap
    self.run()
  File "/usr/lib/python2.7/multiprocessing/process.py", line 114, in run
    self._target(*self._args, **self._kwargs)
  File "./run_sim_global_fcfs_exponential_lognormal_exponential_scan_8_cores.py", line 181, in run_sim
    with open(flow_name, 'w') as f:
IOError: [Errno 36] File name too long: '../../out/fall2017/global_queue_fcfs_exponential_lognormal_exponential_scan/sim_8_global_0.0_global_flow0_exponential_request_poisson_arrival_0.216666666667_2.0_0.0_enqfrontFalse_flow1_lognormal_request_poisson_arrival_0.216666666667_20.0_200.0_0.0_enqfrontFalse_flow2_exponential_request_poisson_arrival_0.216666666667_20.0_0.0_enqfrontFalse_flow0'
Process Process-7:
Traceback (most recent call last):
  File "/usr/lib/python2.7/multiprocessing/process.py", line 258, in _bootstrap
    self.run()
  File "/usr/lib/python2.7/multiprocessing/process.py", line 114, in run
    self._target(*self._args, **self._kwargs)
  File "./run_sim_perflow_first_packet_wait_exponential_lognormal_exponential_scan_8_cores.py", line 184, in run_sim
    with open(flow_name, 'w') as f:
IOError: [Errno 36] File name too long: '../../out/fall2017/perflow_queue_first_packet_wait_exponential_lognormal_exponential_scan/sim_8_perflow_0.0_FirstPacketWaitDequeuePolicy_flow0_exponential_request_poisson_arrival_0.116666666667_2.0_2.0_enqfrontTrue_flow1_lognormal_request_poisson_arrival_0.116666666667_20.0_200.0_2.0_enqfrontFalse_flow2_exponential_request_poisson_arrival_0.116666666667_20.0_2.0_enqfrontTrue_flow0'
Process Process-7:
Traceback (most recent call last):
  File "/usr/lib/python2.7/multiprocessing/process.py", line 258, in _bootstrap
    self.run()
  File "/usr/lib/python2.7/multiprocessing/process.py", line 114, in run
    self._target(*self._args, **self._kwargs)
  File "./run_sim_perflow_longest_load_exponential_lognormal_exponential_scan_8_cores.py", line 184, in run_sim
    with open(flow_name, 'w') as f:
IOError: [Errno 36] File name too long: '../../out/fall2017/perflow_queue_longest_load_exponential_lognormal_exponential_scan/sim_8_perflow_0.0_LongestLoadDequeuePolicy_flow0_exponential_request_poisson_arrival_0.116666666667_2.0_2.0_enqfrontTrue_flow1_lognormal_request_poisson_arrival_0.116666666667_20.0_200.0_2.0_enqfrontFalse_flow2_exponential_request_poisson_arrival_0.116666666667_20.0_2.0_enqfrontTrue_flow0'
Process Process-14:
Traceback (most recent call last):
  File "/usr/lib/python2.7/multiprocessing/process.py", line 258, in _bootstrap
    self.run()
  File "/usr/lib/python2.7/multiprocessing/process.py", line 114, in run
    self._target(*self._args, **self._kwargs)
  File "./run_sim_global_fcfs_exponential_lognormal_exponential_scan_8_cores.py", line 181, in run_sim
    with open(flow_name, 'w') as f:
IOError: [Errno 36] File name too long: '../../out/fall2017/global_queue_fcfs_exponential_lognormal_exponential_scan/sim_8_global_0.0_global_flow0_exponential_request_poisson_arrival_0.233333333333_2.0_0.0_enqfrontFalse_flow1_lognormal_request_poisson_arrival_0.233333333333_20.0_200.0_0.0_enqfrontFalse_flow2_exponential_request_poisson_arrival_0.233333333333_20.0_0.0_enqfrontFalse_flow0'
Process Process-8:
Traceback (most recent call last):
  File "/usr/lib/python2.7/multiprocessing/process.py", line 258, in _bootstrap
    self.run()
  File "/usr/lib/python2.7/multiprocessing/process.py", line 114, in run
    self._target(*self._args, **self._kwargs)
  File "./run_sim_perflow_first_packet_slo_exponential_lognormal_exponential_scan_8_cores.py", line 184, in run_sim
    with open(flow_name, 'w') as f:
IOError: [Errno 36] File name too long: '../../out/fall2017/perflow_queue_first_packet_slo_exponential_lognormal_exponential_scan/sim_8_perflow_0.0_FirstPacketLatencyDequeuePolicy_flow0_exponential_request_poisson_arrival_0.133333333333_2.0_2.0_enqfrontTrue_flow1_lognormal_request_poisson_arrival_0.133333333333_20.0_200.0_2.0_enqfrontFalse_flow2_exponential_request_poisson_arrival_0.133333333333_20.0_2.0_enqfrontTrue_flow0'
Process Process-15:
Traceback (most recent call last):
  File "/usr/lib/python2.7/multiprocessing/process.py", line 258, in _bootstrap
    self.run()
  File "/usr/lib/python2.7/multiprocessing/process.py", line 114, in run
    self._target(*self._args, **self._kwargs)
  File "./run_sim_global_fcfs_exponential_lognormal_exponential_scan_8_cores.py", line 197, in run_sim
    with open(flow_name, 'w') as f:
IOError: [Errno 36] File name too long: '../../out/fall2017/global_queue_fcfs_exponential_lognormal_exponential_scan/sim_8_global_0.0_global_flow0_exponential_request_poisson_arrival_0.25_2.0_0.0_enqfrontFalse_flow1_lognormal_request_poisson_arrival_0.25_20.0_200.0_0.0_enqfrontFalse_flow2_exponential_request_poisson_arrival_0.25_20.0_0.0_enqfrontFalse_flow0.throughput.total'
Process Process-8:
Traceback (most recent call last):
  File "/usr/lib/python2.7/multiprocessing/process.py", line 258, in _bootstrap
    self.run()
  File "/usr/lib/python2.7/multiprocessing/process.py", line 114, in run
    self._target(*self._args, **self._kwargs)
  File "./run_sim_perflow_first_packet_wait_exponential_lognormal_exponential_scan_8_cores.py", line 184, in run_sim
    with open(flow_name, 'w') as f:
IOError: [Errno 36] File name too long: '../../out/fall2017/perflow_queue_first_packet_wait_exponential_lognormal_exponential_scan/sim_8_perflow_0.0_FirstPacketWaitDequeuePolicy_flow0_exponential_request_poisson_arrival_0.133333333333_2.0_2.0_enqfrontTrue_flow1_lognormal_request_poisson_arrival_0.133333333333_20.0_200.0_2.0_enqfrontFalse_flow2_exponential_request_poisson_arrival_0.133333333333_20.0_2.0_enqfrontTrue_flow0'
Process Process-8:
Traceback (most recent call last):
  File "/usr/lib/python2.7/multiprocessing/process.py", line 258, in _bootstrap
    self.run()
  File "/usr/lib/python2.7/multiprocessing/process.py", line 114, in run
    self._target(*self._args, **self._kwargs)
  File "./run_sim_perflow_longest_load_exponential_lognormal_exponential_scan_8_cores.py", line 184, in run_sim
    with open(flow_name, 'w') as f:
IOError: [Errno 36] File name too long: '../../out/fall2017/perflow_queue_longest_load_exponential_lognormal_exponential_scan/sim_8_perflow_0.0_LongestLoadDequeuePolicy_flow0_exponential_request_poisson_arrival_0.133333333333_2.0_2.0_enqfrontTrue_flow1_lognormal_request_poisson_arrival_0.133333333333_20.0_200.0_2.0_enqfrontFalse_flow2_exponential_request_poisson_arrival_0.133333333333_20.0_2.0_enqfrontTrue_flow0'
Process Process-16:
Traceback (most recent call last):
  File "/usr/lib/python2.7/multiprocessing/process.py", line 258, in _bootstrap
    self.run()
  File "/usr/lib/python2.7/multiprocessing/process.py", line 114, in run
    self._target(*self._args, **self._kwargs)
  File "./run_sim_global_fcfs_exponential_lognormal_exponential_scan_8_cores.py", line 181, in run_sim
    with open(flow_name, 'w') as f:
IOError: [Errno 36] File name too long: '../../out/fall2017/global_queue_fcfs_exponential_lognormal_exponential_scan/sim_8_global_0.0_global_flow0_exponential_request_poisson_arrival_0.266666666667_2.0_0.0_enqfrontFalse_flow1_lognormal_request_poisson_arrival_0.266666666667_20.0_200.0_0.0_enqfrontFalse_flow2_exponential_request_poisson_arrival_0.266666666667_20.0_0.0_enqfrontFalse_flow0'
Process Process-9:
Traceback (most recent call last):
  File "/usr/lib/python2.7/multiprocessing/process.py", line 258, in _bootstrap
    self.run()
  File "/usr/lib/python2.7/multiprocessing/process.py", line 114, in run
    self._target(*self._args, **self._kwargs)
  File "./run_sim_perflow_first_packet_wait_exponential_lognormal_exponential_scan_8_cores.py", line 184, in run_sim
    with open(flow_name, 'w') as f:
IOError: [Errno 36] File name too long: '../../out/fall2017/perflow_queue_first_packet_wait_exponential_lognormal_exponential_scan/sim_8_perflow_0.0_FirstPacketWaitDequeuePolicy_flow0_exponential_request_poisson_arrival_0.15_2.0_2.0_enqfrontTrue_flow1_lognormal_request_poisson_arrival_0.15_20.0_200.0_2.0_enqfrontFalse_flow2_exponential_request_poisson_arrival_0.15_20.0_2.0_enqfrontTrue_flow0'
Process Process-9:
Traceback (most recent call last):
  File "/usr/lib/python2.7/multiprocessing/process.py", line 258, in _bootstrap
    self.run()
  File "/usr/lib/python2.7/multiprocessing/process.py", line 114, in run
    self._target(*self._args, **self._kwargs)
  File "./run_sim_perflow_first_packet_slo_exponential_lognormal_exponential_scan_8_cores.py", line 184, in run_sim
    with open(flow_name, 'w') as f:
IOError: [Errno 36] File name too long: '../../out/fall2017/perflow_queue_first_packet_slo_exponential_lognormal_exponential_scan/sim_8_perflow_0.0_FirstPacketLatencyDequeuePolicy_flow0_exponential_request_poisson_arrival_0.15_2.0_2.0_enqfrontTrue_flow1_lognormal_request_poisson_arrival_0.15_20.0_200.0_2.0_enqfrontFalse_flow2_exponential_request_poisson_arrival_0.15_20.0_2.0_enqfrontTrue_flow0'
Process Process-17:
Traceback (most recent call last):
  File "/usr/lib/python2.7/multiprocessing/process.py", line 258, in _bootstrap
    self.run()
  File "/usr/lib/python2.7/multiprocessing/process.py", line 114, in run
    self._target(*self._args, **self._kwargs)
  File "./run_sim_global_fcfs_exponential_lognormal_exponential_scan_8_cores.py", line 181, in run_sim
    with open(flow_name, 'w') as f:
IOError: [Errno 36] File name too long: '../../out/fall2017/global_queue_fcfs_exponential_lognormal_exponential_scan/sim_8_global_0.0_global_flow0_exponential_request_poisson_arrival_0.283333333333_2.0_0.0_enqfrontFalse_flow1_lognormal_request_poisson_arrival_0.283333333333_20.0_200.0_0.0_enqfrontFalse_flow2_exponential_request_poisson_arrival_0.283333333333_20.0_0.0_enqfrontFalse_flow0'
Process Process-9:
Traceback (most recent call last):
  File "/usr/lib/python2.7/multiprocessing/process.py", line 258, in _bootstrap
    self.run()
  File "/usr/lib/python2.7/multiprocessing/process.py", line 114, in run
    self._target(*self._args, **self._kwargs)
  File "./run_sim_perflow_longest_load_exponential_lognormal_exponential_scan_8_cores.py", line 184, in run_sim
    with open(flow_name, 'w') as f:
IOError: [Errno 36] File name too long: '../../out/fall2017/perflow_queue_longest_load_exponential_lognormal_exponential_scan/sim_8_perflow_0.0_LongestLoadDequeuePolicy_flow0_exponential_request_poisson_arrival_0.15_2.0_2.0_enqfrontTrue_flow1_lognormal_request_poisson_arrival_0.15_20.0_200.0_2.0_enqfrontFalse_flow2_exponential_request_poisson_arrival_0.15_20.0_2.0_enqfrontTrue_flow0'
Process Process-18:
Traceback (most recent call last):
  File "/usr/lib/python2.7/multiprocessing/process.py", line 258, in _bootstrap
    self.run()
  File "/usr/lib/python2.7/multiprocessing/process.py", line 114, in run
    self._target(*self._args, **self._kwargs)
  File "./run_sim_global_fcfs_exponential_lognormal_exponential_scan_8_cores.py", line 197, in run_sim
    with open(flow_name, 'w') as f:
IOError: [Errno 36] File name too long: '../../out/fall2017/global_queue_fcfs_exponential_lognormal_exponential_scan/sim_8_global_0.0_global_flow0_exponential_request_poisson_arrival_0.3_2.0_0.0_enqfrontFalse_flow1_lognormal_request_poisson_arrival_0.3_20.0_200.0_0.0_enqfrontFalse_flow2_exponential_request_poisson_arrival_0.3_20.0_0.0_enqfrontFalse_flow0.throughput.total'
Process Process-10:
Traceback (most recent call last):
  File "/usr/lib/python2.7/multiprocessing/process.py", line 258, in _bootstrap
    self.run()
  File "/usr/lib/python2.7/multiprocessing/process.py", line 114, in run
    self._target(*self._args, **self._kwargs)
  File "./run_sim_perflow_first_packet_slo_exponential_lognormal_exponential_scan_8_cores.py", line 184, in run_sim
    with open(flow_name, 'w') as f:
IOError: [Errno 36] File name too long: '../../out/fall2017/perflow_queue_first_packet_slo_exponential_lognormal_exponential_scan/sim_8_perflow_0.0_FirstPacketLatencyDequeuePolicy_flow0_exponential_request_poisson_arrival_0.166666666667_2.0_2.0_enqfrontTrue_flow1_lognormal_request_poisson_arrival_0.166666666667_20.0_200.0_2.0_enqfrontFalse_flow2_exponential_request_poisson_arrival_0.166666666667_20.0_2.0_enqfrontTrue_flow0'
Process Process-19:
Traceback (most recent call last):
  File "/usr/lib/python2.7/multiprocessing/process.py", line 258, in _bootstrap
    self.run()
  File "/usr/lib/python2.7/multiprocessing/process.py", line 114, in run
    self._target(*self._args, **self._kwargs)
  File "./run_sim_global_fcfs_exponential_lognormal_exponential_scan_8_cores.py", line 181, in run_sim
    with open(flow_name, 'w') as f:
IOError: [Errno 36] File name too long: '../../out/fall2017/global_queue_fcfs_exponential_lognormal_exponential_scan/sim_8_global_0.0_global_flow0_exponential_request_poisson_arrival_0.316666666667_2.0_0.0_enqfrontFalse_flow1_lognormal_request_poisson_arrival_0.316666666667_20.0_200.0_0.0_enqfrontFalse_flow2_exponential_request_poisson_arrival_0.316666666667_20.0_0.0_enqfrontFalse_flow0'
Process Process-10:
Traceback (most recent call last):
  File "/usr/lib/python2.7/multiprocessing/process.py", line 258, in _bootstrap
    self.run()
  File "/usr/lib/python2.7/multiprocessing/process.py", line 114, in run
    self._target(*self._args, **self._kwargs)
  File "./run_sim_perflow_first_packet_wait_exponential_lognormal_exponential_scan_8_cores.py", line 184, in run_sim
    with open(flow_name, 'w') as f:
IOError: [Errno 36] File name too long: '../../out/fall2017/perflow_queue_first_packet_wait_exponential_lognormal_exponential_scan/sim_8_perflow_0.0_FirstPacketWaitDequeuePolicy_flow0_exponential_request_poisson_arrival_0.166666666667_2.0_2.0_enqfrontTrue_flow1_lognormal_request_poisson_arrival_0.166666666667_20.0_200.0_2.0_enqfrontFalse_flow2_exponential_request_poisson_arrival_0.166666666667_20.0_2.0_enqfrontTrue_flow0'
Process Process-20:
Traceback (most recent call last):
  File "/usr/lib/python2.7/multiprocessing/process.py", line 258, in _bootstrap
    self.run()
  File "/usr/lib/python2.7/multiprocessing/process.py", line 114, in run
    self._target(*self._args, **self._kwargs)
  File "./run_sim_global_fcfs_exponential_lognormal_exponential_scan_8_cores.py", line 197, in run_sim
    with open(flow_name, 'w') as f:
IOError: [Errno 36] File name too long: '../../out/fall2017/global_queue_fcfs_exponential_lognormal_exponential_scan/sim_8_global_0.0_global_flow0_exponential_request_poisson_arrival_0.32_2.0_0.0_enqfrontFalse_flow1_lognormal_request_poisson_arrival_0.32_20.0_200.0_0.0_enqfrontFalse_flow2_exponential_request_poisson_arrival_0.32_20.0_0.0_enqfrontFalse_flow0.throughput.total'
Process Process-10:
Traceback (most recent call last):
  File "/usr/lib/python2.7/multiprocessing/process.py", line 258, in _bootstrap
    self.run()
  File "/usr/lib/python2.7/multiprocessing/process.py", line 114, in run
    self._target(*self._args, **self._kwargs)
  File "./run_sim_perflow_longest_load_exponential_lognormal_exponential_scan_8_cores.py", line 184, in run_sim
    with open(flow_name, 'w') as f:
IOError: [Errno 36] File name too long: '../../out/fall2017/perflow_queue_longest_load_exponential_lognormal_exponential_scan/sim_8_perflow_0.0_LongestLoadDequeuePolicy_flow0_exponential_request_poisson_arrival_0.166666666667_2.0_2.0_enqfrontTrue_flow1_lognormal_request_poisson_arrival_0.166666666667_20.0_200.0_2.0_enqfrontFalse_flow2_exponential_request_poisson_arrival_0.166666666667_20.0_2.0_enqfrontTrue_flow0'
Process Process-21:
Traceback (most recent call last):
  File "/usr/lib/python2.7/multiprocessing/process.py", line 258, in _bootstrap
    self.run()
  File "/usr/lib/python2.7/multiprocessing/process.py", line 114, in run
    self._target(*self._args, **self._kwargs)
  File "./run_sim_global_fcfs_exponential_lognormal_exponential_scan_8_cores.py", line 181, in run_sim
    with open(flow_name, 'w') as f:
IOError: [Errno 36] File name too long: '../../out/fall2017/global_queue_fcfs_exponential_lognormal_exponential_scan/sim_8_global_0.0_global_flow0_exponential_request_poisson_arrival_0.323333333333_2.0_0.0_enqfrontFalse_flow1_lognormal_request_poisson_arrival_0.323333333333_20.0_200.0_0.0_enqfrontFalse_flow2_exponential_request_poisson_arrival_0.323333333333_20.0_0.0_enqfrontFalse_flow0'
Process Process-22:
Traceback (most recent call last):
  File "/usr/lib/python2.7/multiprocessing/process.py", line 258, in _bootstrap
    self.run()
  File "/usr/lib/python2.7/multiprocessing/process.py", line 114, in run
    self._target(*self._args, **self._kwargs)
  File "./run_sim_global_fcfs_exponential_lognormal_exponential_scan_8_cores.py", line 181, in run_sim
    with open(flow_name, 'w') as f:
IOError: [Errno 36] File name too long: '../../out/fall2017/global_queue_fcfs_exponential_lognormal_exponential_scan/sim_8_global_0.0_global_flow0_exponential_request_poisson_arrival_0.326666666667_2.0_0.0_enqfrontFalse_flow1_lognormal_request_poisson_arrival_0.326666666667_20.0_200.0_0.0_enqfrontFalse_flow2_exponential_request_poisson_arrival_0.326666666667_20.0_0.0_enqfrontFalse_flow0'
Process Process-23:
Traceback (most recent call last):
  File "/usr/lib/python2.7/multiprocessing/process.py", line 258, in _bootstrap
    self.run()
  File "/usr/lib/python2.7/multiprocessing/process.py", line 114, in run
    self._target(*self._args, **self._kwargs)
  File "./run_sim_global_fcfs_exponential_lognormal_exponential_scan_8_cores.py", line 197, in run_sim
    with open(flow_name, 'w') as f:
IOError: [Errno 36] File name too long: '../../out/fall2017/global_queue_fcfs_exponential_lognormal_exponential_scan/sim_8_global_0.0_global_flow0_exponential_request_poisson_arrival_0.33_2.0_0.0_enqfrontFalse_flow1_lognormal_request_poisson_arrival_0.33_20.0_200.0_0.0_enqfrontFalse_flow2_exponential_request_poisson_arrival_0.33_20.0_0.0_enqfrontFalse_flow0.throughput.total'
Winding down
Process Process-11:
Traceback (most recent call last):
  File "/usr/lib/python2.7/multiprocessing/process.py", line 258, in _bootstrap
    self.run()
  File "/usr/lib/python2.7/multiprocessing/process.py", line 114, in run
    self._target(*self._args, **self._kwargs)
  File "./run_sim_perflow_first_packet_wait_exponential_lognormal_exponential_scan_8_cores.py", line 184, in run_sim
    with open(flow_name, 'w') as f:
IOError: [Errno 36] File name too long: '../../out/fall2017/perflow_queue_first_packet_wait_exponential_lognormal_exponential_scan/sim_8_perflow_0.0_FirstPacketWaitDequeuePolicy_flow0_exponential_request_poisson_arrival_0.183333333333_2.0_2.0_enqfrontTrue_flow1_lognormal_request_poisson_arrival_0.183333333333_20.0_200.0_2.0_enqfrontFalse_flow2_exponential_request_poisson_arrival_0.183333333333_20.0_2.0_enqfrontTrue_flow0'
Process Process-11:
Traceback (most recent call last):
  File "/usr/lib/python2.7/multiprocessing/process.py", line 258, in _bootstrap
    self.run()
  File "/usr/lib/python2.7/multiprocessing/process.py", line 114, in run
    self._target(*self._args, **self._kwargs)
  File "./run_sim_perflow_first_packet_slo_exponential_lognormal_exponential_scan_8_cores.py", line 184, in run_sim
    with open(flow_name, 'w') as f:
IOError: [Errno 36] File name too long: '../../out/fall2017/perflow_queue_first_packet_slo_exponential_lognormal_exponential_scan/sim_8_perflow_0.0_FirstPacketLatencyDequeuePolicy_flow0_exponential_request_poisson_arrival_0.183333333333_2.0_2.0_enqfrontTrue_flow1_lognormal_request_poisson_arrival_0.183333333333_20.0_200.0_2.0_enqfrontFalse_flow2_exponential_request_poisson_arrival_0.183333333333_20.0_2.0_enqfrontTrue_flow0'
Process Process-11:
Traceback (most recent call last):
  File "/usr/lib/python2.7/multiprocessing/process.py", line 258, in _bootstrap
    self.run()
  File "/usr/lib/python2.7/multiprocessing/process.py", line 114, in run
    self._target(*self._args, **self._kwargs)
  File "./run_sim_perflow_longest_load_exponential_lognormal_exponential_scan_8_cores.py", line 184, in run_sim
    with open(flow_name, 'w') as f:
IOError: [Errno 36] File name too long: '../../out/fall2017/perflow_queue_longest_load_exponential_lognormal_exponential_scan/sim_8_perflow_0.0_LongestLoadDequeuePolicy_flow0_exponential_request_poisson_arrival_0.183333333333_2.0_2.0_enqfrontTrue_flow1_lognormal_request_poisson_arrival_0.183333333333_20.0_200.0_2.0_enqfrontFalse_flow2_exponential_request_poisson_arrival_0.183333333333_20.0_2.0_enqfrontTrue_flow0'
Process Process-12:
Traceback (most recent call last):
  File "/usr/lib/python2.7/multiprocessing/process.py", line 258, in _bootstrap
    self.run()
  File "/usr/lib/python2.7/multiprocessing/process.py", line 114, in run
    self._target(*self._args, **self._kwargs)
  File "./run_sim_perflow_first_packet_slo_exponential_lognormal_exponential_scan_8_cores.py", line 184, in run_sim
    with open(flow_name, 'w') as f:
IOError: [Errno 36] File name too long: '../../out/fall2017/perflow_queue_first_packet_slo_exponential_lognormal_exponential_scan/sim_8_perflow_0.0_FirstPacketLatencyDequeuePolicy_flow0_exponential_request_poisson_arrival_0.2_2.0_2.0_enqfrontTrue_flow1_lognormal_request_poisson_arrival_0.2_20.0_200.0_2.0_enqfrontFalse_flow2_exponential_request_poisson_arrival_0.2_20.0_2.0_enqfrontTrue_flow0'
Process Process-12:
Traceback (most recent call last):
  File "/usr/lib/python2.7/multiprocessing/process.py", line 258, in _bootstrap
    self.run()
  File "/usr/lib/python2.7/multiprocessing/process.py", line 114, in run
    self._target(*self._args, **self._kwargs)
  File "./run_sim_perflow_first_packet_wait_exponential_lognormal_exponential_scan_8_cores.py", line 184, in run_sim
    with open(flow_name, 'w') as f:
IOError: [Errno 36] File name too long: '../../out/fall2017/perflow_queue_first_packet_wait_exponential_lognormal_exponential_scan/sim_8_perflow_0.0_FirstPacketWaitDequeuePolicy_flow0_exponential_request_poisson_arrival_0.2_2.0_2.0_enqfrontTrue_flow1_lognormal_request_poisson_arrival_0.2_20.0_200.0_2.0_enqfrontFalse_flow2_exponential_request_poisson_arrival_0.2_20.0_2.0_enqfrontTrue_flow0'
Process Process-12:
Traceback (most recent call last):
  File "/usr/lib/python2.7/multiprocessing/process.py", line 258, in _bootstrap
    self.run()
  File "/usr/lib/python2.7/multiprocessing/process.py", line 114, in run
    self._target(*self._args, **self._kwargs)
  File "./run_sim_perflow_longest_load_exponential_lognormal_exponential_scan_8_cores.py", line 184, in run_sim
    with open(flow_name, 'w') as f:
IOError: [Errno 36] File name too long: '../../out/fall2017/perflow_queue_longest_load_exponential_lognormal_exponential_scan/sim_8_perflow_0.0_LongestLoadDequeuePolicy_flow0_exponential_request_poisson_arrival_0.2_2.0_2.0_enqfrontTrue_flow1_lognormal_request_poisson_arrival_0.2_20.0_200.0_2.0_enqfrontFalse_flow2_exponential_request_poisson_arrival_0.2_20.0_2.0_enqfrontTrue_flow0'
Process Process-13:
Traceback (most recent call last):
  File "/usr/lib/python2.7/multiprocessing/process.py", line 258, in _bootstrap
    self.run()
  File "/usr/lib/python2.7/multiprocessing/process.py", line 114, in run
    self._target(*self._args, **self._kwargs)
  File "./run_sim_perflow_first_packet_slo_exponential_lognormal_exponential_scan_8_cores.py", line 184, in run_sim
    with open(flow_name, 'w') as f:
IOError: [Errno 36] File name too long: '../../out/fall2017/perflow_queue_first_packet_slo_exponential_lognormal_exponential_scan/sim_8_perflow_0.0_FirstPacketLatencyDequeuePolicy_flow0_exponential_request_poisson_arrival_0.216666666667_2.0_2.0_enqfrontTrue_flow1_lognormal_request_poisson_arrival_0.216666666667_20.0_200.0_2.0_enqfrontFalse_flow2_exponential_request_poisson_arrival_0.216666666667_20.0_2.0_enqfrontTrue_flow0'
Process Process-13:
Traceback (most recent call last):
  File "/usr/lib/python2.7/multiprocessing/process.py", line 258, in _bootstrap
    self.run()
  File "/usr/lib/python2.7/multiprocessing/process.py", line 114, in run
    self._target(*self._args, **self._kwargs)
  File "./run_sim_perflow_first_packet_wait_exponential_lognormal_exponential_scan_8_cores.py", line 184, in run_sim
    with open(flow_name, 'w') as f:
IOError: [Errno 36] File name too long: '../../out/fall2017/perflow_queue_first_packet_wait_exponential_lognormal_exponential_scan/sim_8_perflow_0.0_FirstPacketWaitDequeuePolicy_flow0_exponential_request_poisson_arrival_0.216666666667_2.0_2.0_enqfrontTrue_flow1_lognormal_request_poisson_arrival_0.216666666667_20.0_200.0_2.0_enqfrontFalse_flow2_exponential_request_poisson_arrival_0.216666666667_20.0_2.0_enqfrontTrue_flow0'
Process Process-13:
Traceback (most recent call last):
  File "/usr/lib/python2.7/multiprocessing/process.py", line 258, in _bootstrap
    self.run()
  File "/usr/lib/python2.7/multiprocessing/process.py", line 114, in run
    self._target(*self._args, **self._kwargs)
  File "./run_sim_perflow_longest_load_exponential_lognormal_exponential_scan_8_cores.py", line 184, in run_sim
    with open(flow_name, 'w') as f:
IOError: [Errno 36] File name too long: '../../out/fall2017/perflow_queue_longest_load_exponential_lognormal_exponential_scan/sim_8_perflow_0.0_LongestLoadDequeuePolicy_flow0_exponential_request_poisson_arrival_0.216666666667_2.0_2.0_enqfrontTrue_flow1_lognormal_request_poisson_arrival_0.216666666667_20.0_200.0_2.0_enqfrontFalse_flow2_exponential_request_poisson_arrival_0.216666666667_20.0_2.0_enqfrontTrue_flow0'
Process Process-14:
Traceback (most recent call last):
  File "/usr/lib/python2.7/multiprocessing/process.py", line 258, in _bootstrap
    self.run()
  File "/usr/lib/python2.7/multiprocessing/process.py", line 114, in run
    self._target(*self._args, **self._kwargs)
  File "./run_sim_perflow_first_packet_wait_exponential_lognormal_exponential_scan_8_cores.py", line 184, in run_sim
    with open(flow_name, 'w') as f:
IOError: [Errno 36] File name too long: '../../out/fall2017/perflow_queue_first_packet_wait_exponential_lognormal_exponential_scan/sim_8_perflow_0.0_FirstPacketWaitDequeuePolicy_flow0_exponential_request_poisson_arrival_0.233333333333_2.0_2.0_enqfrontTrue_flow1_lognormal_request_poisson_arrival_0.233333333333_20.0_200.0_2.0_enqfrontFalse_flow2_exponential_request_poisson_arrival_0.233333333333_20.0_2.0_enqfrontTrue_flow0'
Process Process-14:
Traceback (most recent call last):
  File "/usr/lib/python2.7/multiprocessing/process.py", line 258, in _bootstrap
    self.run()
  File "/usr/lib/python2.7/multiprocessing/process.py", line 114, in run
    self._target(*self._args, **self._kwargs)
  File "./run_sim_perflow_first_packet_slo_exponential_lognormal_exponential_scan_8_cores.py", line 184, in run_sim
    with open(flow_name, 'w') as f:
IOError: [Errno 36] File name too long: '../../out/fall2017/perflow_queue_first_packet_slo_exponential_lognormal_exponential_scan/sim_8_perflow_0.0_FirstPacketLatencyDequeuePolicy_flow0_exponential_request_poisson_arrival_0.233333333333_2.0_2.0_enqfrontTrue_flow1_lognormal_request_poisson_arrival_0.233333333333_20.0_200.0_2.0_enqfrontFalse_flow2_exponential_request_poisson_arrival_0.233333333333_20.0_2.0_enqfrontTrue_flow0'
Process Process-14:
Traceback (most recent call last):
  File "/usr/lib/python2.7/multiprocessing/process.py", line 258, in _bootstrap
    self.run()
  File "/usr/lib/python2.7/multiprocessing/process.py", line 114, in run
    self._target(*self._args, **self._kwargs)
  File "./run_sim_perflow_longest_load_exponential_lognormal_exponential_scan_8_cores.py", line 184, in run_sim
    with open(flow_name, 'w') as f:
IOError: [Errno 36] File name too long: '../../out/fall2017/perflow_queue_longest_load_exponential_lognormal_exponential_scan/sim_8_perflow_0.0_LongestLoadDequeuePolicy_flow0_exponential_request_poisson_arrival_0.233333333333_2.0_2.0_enqfrontTrue_flow1_lognormal_request_poisson_arrival_0.233333333333_20.0_200.0_2.0_enqfrontFalse_flow2_exponential_request_poisson_arrival_0.233333333333_20.0_2.0_enqfrontTrue_flow0'
Process Process-15:
Traceback (most recent call last):
  File "/usr/lib/python2.7/multiprocessing/process.py", line 258, in _bootstrap
    self.run()
  File "/usr/lib/python2.7/multiprocessing/process.py", line 114, in run
    self._target(*self._args, **self._kwargs)
  File "./run_sim_perflow_first_packet_slo_exponential_lognormal_exponential_scan_8_cores.py", line 184, in run_sim
    with open(flow_name, 'w') as f:
IOError: [Errno 36] File name too long: '../../out/fall2017/perflow_queue_first_packet_slo_exponential_lognormal_exponential_scan/sim_8_perflow_0.0_FirstPacketLatencyDequeuePolicy_flow0_exponential_request_poisson_arrival_0.25_2.0_2.0_enqfrontTrue_flow1_lognormal_request_poisson_arrival_0.25_20.0_200.0_2.0_enqfrontFalse_flow2_exponential_request_poisson_arrival_0.25_20.0_2.0_enqfrontTrue_flow0'
Process Process-15:
Traceback (most recent call last):
  File "/usr/lib/python2.7/multiprocessing/process.py", line 258, in _bootstrap
    self.run()
  File "/usr/lib/python2.7/multiprocessing/process.py", line 114, in run
    self._target(*self._args, **self._kwargs)
  File "./run_sim_perflow_first_packet_wait_exponential_lognormal_exponential_scan_8_cores.py", line 184, in run_sim
    with open(flow_name, 'w') as f:
IOError: [Errno 36] File name too long: '../../out/fall2017/perflow_queue_first_packet_wait_exponential_lognormal_exponential_scan/sim_8_perflow_0.0_FirstPacketWaitDequeuePolicy_flow0_exponential_request_poisson_arrival_0.25_2.0_2.0_enqfrontTrue_flow1_lognormal_request_poisson_arrival_0.25_20.0_200.0_2.0_enqfrontFalse_flow2_exponential_request_poisson_arrival_0.25_20.0_2.0_enqfrontTrue_flow0'
Process Process-15:
Traceback (most recent call last):
  File "/usr/lib/python2.7/multiprocessing/process.py", line 258, in _bootstrap
    self.run()
  File "/usr/lib/python2.7/multiprocessing/process.py", line 114, in run
    self._target(*self._args, **self._kwargs)
  File "./run_sim_perflow_longest_load_exponential_lognormal_exponential_scan_8_cores.py", line 184, in run_sim
    with open(flow_name, 'w') as f:
IOError: [Errno 36] File name too long: '../../out/fall2017/perflow_queue_longest_load_exponential_lognormal_exponential_scan/sim_8_perflow_0.0_LongestLoadDequeuePolicy_flow0_exponential_request_poisson_arrival_0.25_2.0_2.0_enqfrontTrue_flow1_lognormal_request_poisson_arrival_0.25_20.0_200.0_2.0_enqfrontFalse_flow2_exponential_request_poisson_arrival_0.25_20.0_2.0_enqfrontTrue_flow0'
Process Process-16:
Traceback (most recent call last):
  File "/usr/lib/python2.7/multiprocessing/process.py", line 258, in _bootstrap
    self.run()
  File "/usr/lib/python2.7/multiprocessing/process.py", line 114, in run
    self._target(*self._args, **self._kwargs)
  File "./run_sim_perflow_first_packet_wait_exponential_lognormal_exponential_scan_8_cores.py", line 184, in run_sim
    with open(flow_name, 'w') as f:
IOError: [Errno 36] File name too long: '../../out/fall2017/perflow_queue_first_packet_wait_exponential_lognormal_exponential_scan/sim_8_perflow_0.0_FirstPacketWaitDequeuePolicy_flow0_exponential_request_poisson_arrival_0.266666666667_2.0_2.0_enqfrontTrue_flow1_lognormal_request_poisson_arrival_0.266666666667_20.0_200.0_2.0_enqfrontFalse_flow2_exponential_request_poisson_arrival_0.266666666667_20.0_2.0_enqfrontTrue_flow0'
Process Process-16:
Traceback (most recent call last):
  File "/usr/lib/python2.7/multiprocessing/process.py", line 258, in _bootstrap
    self.run()
  File "/usr/lib/python2.7/multiprocessing/process.py", line 114, in run
    self._target(*self._args, **self._kwargs)
  File "./run_sim_perflow_longest_load_exponential_lognormal_exponential_scan_8_cores.py", line 184, in run_sim
    with open(flow_name, 'w') as f:
IOError: [Errno 36] File name too long: '../../out/fall2017/perflow_queue_longest_load_exponential_lognormal_exponential_scan/sim_8_perflow_0.0_LongestLoadDequeuePolicy_flow0_exponential_request_poisson_arrival_0.266666666667_2.0_2.0_enqfrontTrue_flow1_lognormal_request_poisson_arrival_0.266666666667_20.0_200.0_2.0_enqfrontFalse_flow2_exponential_request_poisson_arrival_0.266666666667_20.0_2.0_enqfrontTrue_flow0'
Process Process-16:
Traceback (most recent call last):
  File "/usr/lib/python2.7/multiprocessing/process.py", line 258, in _bootstrap
    self.run()
  File "/usr/lib/python2.7/multiprocessing/process.py", line 114, in run
    self._target(*self._args, **self._kwargs)
  File "./run_sim_perflow_first_packet_slo_exponential_lognormal_exponential_scan_8_cores.py", line 184, in run_sim
    with open(flow_name, 'w') as f:
IOError: [Errno 36] File name too long: '../../out/fall2017/perflow_queue_first_packet_slo_exponential_lognormal_exponential_scan/sim_8_perflow_0.0_FirstPacketLatencyDequeuePolicy_flow0_exponential_request_poisson_arrival_0.266666666667_2.0_2.0_enqfrontTrue_flow1_lognormal_request_poisson_arrival_0.266666666667_20.0_200.0_2.0_enqfrontFalse_flow2_exponential_request_poisson_arrival_0.266666666667_20.0_2.0_enqfrontTrue_flow0'
Process Process-17:
Traceback (most recent call last):
  File "/usr/lib/python2.7/multiprocessing/process.py", line 258, in _bootstrap
    self.run()
  File "/usr/lib/python2.7/multiprocessing/process.py", line 114, in run
    self._target(*self._args, **self._kwargs)
  File "./run_sim_perflow_first_packet_wait_exponential_lognormal_exponential_scan_8_cores.py", line 184, in run_sim
    with open(flow_name, 'w') as f:
IOError: [Errno 36] File name too long: '../../out/fall2017/perflow_queue_first_packet_wait_exponential_lognormal_exponential_scan/sim_8_perflow_0.0_FirstPacketWaitDequeuePolicy_flow0_exponential_request_poisson_arrival_0.283333333333_2.0_2.0_enqfrontTrue_flow1_lognormal_request_poisson_arrival_0.283333333333_20.0_200.0_2.0_enqfrontFalse_flow2_exponential_request_poisson_arrival_0.283333333333_20.0_2.0_enqfrontTrue_flow0'
Process Process-17:
Traceback (most recent call last):
  File "/usr/lib/python2.7/multiprocessing/process.py", line 258, in _bootstrap
    self.run()
  File "/usr/lib/python2.7/multiprocessing/process.py", line 114, in run
    self._target(*self._args, **self._kwargs)
  File "./run_sim_perflow_first_packet_slo_exponential_lognormal_exponential_scan_8_cores.py", line 184, in run_sim
    with open(flow_name, 'w') as f:
IOError: [Errno 36] File name too long: '../../out/fall2017/perflow_queue_first_packet_slo_exponential_lognormal_exponential_scan/sim_8_perflow_0.0_FirstPacketLatencyDequeuePolicy_flow0_exponential_request_poisson_arrival_0.283333333333_2.0_2.0_enqfrontTrue_flow1_lognormal_request_poisson_arrival_0.283333333333_20.0_200.0_2.0_enqfrontFalse_flow2_exponential_request_poisson_arrival_0.283333333333_20.0_2.0_enqfrontTrue_flow0'
Process Process-17:
Traceback (most recent call last):
  File "/usr/lib/python2.7/multiprocessing/process.py", line 258, in _bootstrap
    self.run()
  File "/usr/lib/python2.7/multiprocessing/process.py", line 114, in run
    self._target(*self._args, **self._kwargs)
  File "./run_sim_perflow_longest_load_exponential_lognormal_exponential_scan_8_cores.py", line 184, in run_sim
    with open(flow_name, 'w') as f:
IOError: [Errno 36] File name too long: '../../out/fall2017/perflow_queue_longest_load_exponential_lognormal_exponential_scan/sim_8_perflow_0.0_LongestLoadDequeuePolicy_flow0_exponential_request_poisson_arrival_0.283333333333_2.0_2.0_enqfrontTrue_flow1_lognormal_request_poisson_arrival_0.283333333333_20.0_200.0_2.0_enqfrontFalse_flow2_exponential_request_poisson_arrival_0.283333333333_20.0_2.0_enqfrontTrue_flow0'
Process Process-18:
Traceback (most recent call last):
  File "/usr/lib/python2.7/multiprocessing/process.py", line 258, in _bootstrap
    self.run()
  File "/usr/lib/python2.7/multiprocessing/process.py", line 114, in run
    self._target(*self._args, **self._kwargs)
  File "./run_sim_perflow_first_packet_wait_exponential_lognormal_exponential_scan_8_cores.py", line 184, in run_sim
    with open(flow_name, 'w') as f:
IOError: [Errno 36] File name too long: '../../out/fall2017/perflow_queue_first_packet_wait_exponential_lognormal_exponential_scan/sim_8_perflow_0.0_FirstPacketWaitDequeuePolicy_flow0_exponential_request_poisson_arrival_0.3_2.0_2.0_enqfrontTrue_flow1_lognormal_request_poisson_arrival_0.3_20.0_200.0_2.0_enqfrontFalse_flow2_exponential_request_poisson_arrival_0.3_20.0_2.0_enqfrontTrue_flow0'
Process Process-18:
Traceback (most recent call last):
  File "/usr/lib/python2.7/multiprocessing/process.py", line 258, in _bootstrap
    self.run()
  File "/usr/lib/python2.7/multiprocessing/process.py", line 114, in run
    self._target(*self._args, **self._kwargs)
  File "./run_sim_perflow_first_packet_slo_exponential_lognormal_exponential_scan_8_cores.py", line 184, in run_sim
    with open(flow_name, 'w') as f:
IOError: [Errno 36] File name too long: '../../out/fall2017/perflow_queue_first_packet_slo_exponential_lognormal_exponential_scan/sim_8_perflow_0.0_FirstPacketLatencyDequeuePolicy_flow0_exponential_request_poisson_arrival_0.3_2.0_2.0_enqfrontTrue_flow1_lognormal_request_poisson_arrival_0.3_20.0_200.0_2.0_enqfrontFalse_flow2_exponential_request_poisson_arrival_0.3_20.0_2.0_enqfrontTrue_flow0'
Process Process-18:
Traceback (most recent call last):
  File "/usr/lib/python2.7/multiprocessing/process.py", line 258, in _bootstrap
    self.run()
  File "/usr/lib/python2.7/multiprocessing/process.py", line 114, in run
    self._target(*self._args, **self._kwargs)
  File "./run_sim_perflow_longest_load_exponential_lognormal_exponential_scan_8_cores.py", line 184, in run_sim
    with open(flow_name, 'w') as f:
IOError: [Errno 36] File name too long: '../../out/fall2017/perflow_queue_longest_load_exponential_lognormal_exponential_scan/sim_8_perflow_0.0_LongestLoadDequeuePolicy_flow0_exponential_request_poisson_arrival_0.3_2.0_2.0_enqfrontTrue_flow1_lognormal_request_poisson_arrival_0.3_20.0_200.0_2.0_enqfrontFalse_flow2_exponential_request_poisson_arrival_0.3_20.0_2.0_enqfrontTrue_flow0'
Process Process-19:
Traceback (most recent call last):
  File "/usr/lib/python2.7/multiprocessing/process.py", line 258, in _bootstrap
    self.run()
  File "/usr/lib/python2.7/multiprocessing/process.py", line 114, in run
    self._target(*self._args, **self._kwargs)
  File "./run_sim_perflow_first_packet_wait_exponential_lognormal_exponential_scan_8_cores.py", line 184, in run_sim
    with open(flow_name, 'w') as f:
IOError: [Errno 36] File name too long: '../../out/fall2017/perflow_queue_first_packet_wait_exponential_lognormal_exponential_scan/sim_8_perflow_0.0_FirstPacketWaitDequeuePolicy_flow0_exponential_request_poisson_arrival_0.316666666667_2.0_2.0_enqfrontTrue_flow1_lognormal_request_poisson_arrival_0.316666666667_20.0_200.0_2.0_enqfrontFalse_flow2_exponential_request_poisson_arrival_0.316666666667_20.0_2.0_enqfrontTrue_flow0'
Process Process-19:
Traceback (most recent call last):
  File "/usr/lib/python2.7/multiprocessing/process.py", line 258, in _bootstrap
    self.run()
  File "/usr/lib/python2.7/multiprocessing/process.py", line 114, in run
    self._target(*self._args, **self._kwargs)
  File "./run_sim_perflow_first_packet_slo_exponential_lognormal_exponential_scan_8_cores.py", line 184, in run_sim
    with open(flow_name, 'w') as f:
IOError: [Errno 36] File name too long: '../../out/fall2017/perflow_queue_first_packet_slo_exponential_lognormal_exponential_scan/sim_8_perflow_0.0_FirstPacketLatencyDequeuePolicy_flow0_exponential_request_poisson_arrival_0.316666666667_2.0_2.0_enqfrontTrue_flow1_lognormal_request_poisson_arrival_0.316666666667_20.0_200.0_2.0_enqfrontFalse_flow2_exponential_request_poisson_arrival_0.316666666667_20.0_2.0_enqfrontTrue_flow0'
Process Process-19:
Traceback (most recent call last):
  File "/usr/lib/python2.7/multiprocessing/process.py", line 258, in _bootstrap
    self.run()
  File "/usr/lib/python2.7/multiprocessing/process.py", line 114, in run
    self._target(*self._args, **self._kwargs)
  File "./run_sim_perflow_longest_load_exponential_lognormal_exponential_scan_8_cores.py", line 184, in run_sim
    with open(flow_name, 'w') as f:
IOError: [Errno 36] File name too long: '../../out/fall2017/perflow_queue_longest_load_exponential_lognormal_exponential_scan/sim_8_perflow_0.0_LongestLoadDequeuePolicy_flow0_exponential_request_poisson_arrival_0.316666666667_2.0_2.0_enqfrontTrue_flow1_lognormal_request_poisson_arrival_0.316666666667_20.0_200.0_2.0_enqfrontFalse_flow2_exponential_request_poisson_arrival_0.316666666667_20.0_2.0_enqfrontTrue_flow0'
Process Process-20:
Traceback (most recent call last):
  File "/usr/lib/python2.7/multiprocessing/process.py", line 258, in _bootstrap
    self.run()
  File "/usr/lib/python2.7/multiprocessing/process.py", line 114, in run
    self._target(*self._args, **self._kwargs)
  File "./run_sim_perflow_first_packet_wait_exponential_lognormal_exponential_scan_8_cores.py", line 184, in run_sim
    with open(flow_name, 'w') as f:
IOError: [Errno 36] File name too long: '../../out/fall2017/perflow_queue_first_packet_wait_exponential_lognormal_exponential_scan/sim_8_perflow_0.0_FirstPacketWaitDequeuePolicy_flow0_exponential_request_poisson_arrival_0.32_2.0_2.0_enqfrontTrue_flow1_lognormal_request_poisson_arrival_0.32_20.0_200.0_2.0_enqfrontFalse_flow2_exponential_request_poisson_arrival_0.32_20.0_2.0_enqfrontTrue_flow0'
Process Process-20:
Traceback (most recent call last):
  File "/usr/lib/python2.7/multiprocessing/process.py", line 258, in _bootstrap
    self.run()
  File "/usr/lib/python2.7/multiprocessing/process.py", line 114, in run
    self._target(*self._args, **self._kwargs)
  File "./run_sim_perflow_first_packet_slo_exponential_lognormal_exponential_scan_8_cores.py", line 184, in run_sim
    with open(flow_name, 'w') as f:
IOError: [Errno 36] File name too long: '../../out/fall2017/perflow_queue_first_packet_slo_exponential_lognormal_exponential_scan/sim_8_perflow_0.0_FirstPacketLatencyDequeuePolicy_flow0_exponential_request_poisson_arrival_0.32_2.0_2.0_enqfrontTrue_flow1_lognormal_request_poisson_arrival_0.32_20.0_200.0_2.0_enqfrontFalse_flow2_exponential_request_poisson_arrival_0.32_20.0_2.0_enqfrontTrue_flow0'
Process Process-20:
Traceback (most recent call last):
  File "/usr/lib/python2.7/multiprocessing/process.py", line 258, in _bootstrap
    self.run()
  File "/usr/lib/python2.7/multiprocessing/process.py", line 114, in run
    self._target(*self._args, **self._kwargs)
  File "./run_sim_perflow_longest_load_exponential_lognormal_exponential_scan_8_cores.py", line 184, in run_sim
    with open(flow_name, 'w') as f:
IOError: [Errno 36] File name too long: '../../out/fall2017/perflow_queue_longest_load_exponential_lognormal_exponential_scan/sim_8_perflow_0.0_LongestLoadDequeuePolicy_flow0_exponential_request_poisson_arrival_0.32_2.0_2.0_enqfrontTrue_flow1_lognormal_request_poisson_arrival_0.32_20.0_200.0_2.0_enqfrontFalse_flow2_exponential_request_poisson_arrival_0.32_20.0_2.0_enqfrontTrue_flow0'
Process Process-21:
Traceback (most recent call last):
  File "/usr/lib/python2.7/multiprocessing/process.py", line 258, in _bootstrap
    self.run()
  File "/usr/lib/python2.7/multiprocessing/process.py", line 114, in run
    self._target(*self._args, **self._kwargs)
  File "./run_sim_perflow_first_packet_wait_exponential_lognormal_exponential_scan_8_cores.py", line 184, in run_sim
    with open(flow_name, 'w') as f:
IOError: [Errno 36] File name too long: '../../out/fall2017/perflow_queue_first_packet_wait_exponential_lognormal_exponential_scan/sim_8_perflow_0.0_FirstPacketWaitDequeuePolicy_flow0_exponential_request_poisson_arrival_0.323333333333_2.0_2.0_enqfrontTrue_flow1_lognormal_request_poisson_arrival_0.323333333333_20.0_200.0_2.0_enqfrontFalse_flow2_exponential_request_poisson_arrival_0.323333333333_20.0_2.0_enqfrontTrue_flow0'
Process Process-21:
Traceback (most recent call last):
  File "/usr/lib/python2.7/multiprocessing/process.py", line 258, in _bootstrap
    self.run()
  File "/usr/lib/python2.7/multiprocessing/process.py", line 114, in run
    self._target(*self._args, **self._kwargs)
  File "./run_sim_perflow_first_packet_slo_exponential_lognormal_exponential_scan_8_cores.py", line 184, in run_sim
    with open(flow_name, 'w') as f:
IOError: [Errno 36] File name too long: '../../out/fall2017/perflow_queue_first_packet_slo_exponential_lognormal_exponential_scan/sim_8_perflow_0.0_FirstPacketLatencyDequeuePolicy_flow0_exponential_request_poisson_arrival_0.323333333333_2.0_2.0_enqfrontTrue_flow1_lognormal_request_poisson_arrival_0.323333333333_20.0_200.0_2.0_enqfrontFalse_flow2_exponential_request_poisson_arrival_0.323333333333_20.0_2.0_enqfrontTrue_flow0'
Process Process-21:
Traceback (most recent call last):
  File "/usr/lib/python2.7/multiprocessing/process.py", line 258, in _bootstrap
    self.run()
  File "/usr/lib/python2.7/multiprocessing/process.py", line 114, in run
    self._target(*self._args, **self._kwargs)
  File "./run_sim_perflow_longest_load_exponential_lognormal_exponential_scan_8_cores.py", line 184, in run_sim
    with open(flow_name, 'w') as f:
IOError: [Errno 36] File name too long: '../../out/fall2017/perflow_queue_longest_load_exponential_lognormal_exponential_scan/sim_8_perflow_0.0_LongestLoadDequeuePolicy_flow0_exponential_request_poisson_arrival_0.323333333333_2.0_2.0_enqfrontTrue_flow1_lognormal_request_poisson_arrival_0.323333333333_20.0_200.0_2.0_enqfrontFalse_flow2_exponential_request_poisson_arrival_0.323333333333_20.0_2.0_enqfrontTrue_flow0'
Process Process-22:
Traceback (most recent call last):
  File "/usr/lib/python2.7/multiprocessing/process.py", line 258, in _bootstrap
    self.run()
  File "/usr/lib/python2.7/multiprocessing/process.py", line 114, in run
    self._target(*self._args, **self._kwargs)
  File "./run_sim_perflow_first_packet_wait_exponential_lognormal_exponential_scan_8_cores.py", line 184, in run_sim
    with open(flow_name, 'w') as f:
IOError: [Errno 36] File name too long: '../../out/fall2017/perflow_queue_first_packet_wait_exponential_lognormal_exponential_scan/sim_8_perflow_0.0_FirstPacketWaitDequeuePolicy_flow0_exponential_request_poisson_arrival_0.326666666667_2.0_2.0_enqfrontTrue_flow1_lognormal_request_poisson_arrival_0.326666666667_20.0_200.0_2.0_enqfrontFalse_flow2_exponential_request_poisson_arrival_0.326666666667_20.0_2.0_enqfrontTrue_flow0'
Process Process-22:
Traceback (most recent call last):
  File "/usr/lib/python2.7/multiprocessing/process.py", line 258, in _bootstrap
    self.run()
  File "/usr/lib/python2.7/multiprocessing/process.py", line 114, in run
    self._target(*self._args, **self._kwargs)
  File "./run_sim_perflow_first_packet_slo_exponential_lognormal_exponential_scan_8_cores.py", line 184, in run_sim
    with open(flow_name, 'w') as f:
IOError: [Errno 36] File name too long: '../../out/fall2017/perflow_queue_first_packet_slo_exponential_lognormal_exponential_scan/sim_8_perflow_0.0_FirstPacketLatencyDequeuePolicy_flow0_exponential_request_poisson_arrival_0.326666666667_2.0_2.0_enqfrontTrue_flow1_lognormal_request_poisson_arrival_0.326666666667_20.0_200.0_2.0_enqfrontFalse_flow2_exponential_request_poisson_arrival_0.326666666667_20.0_2.0_enqfrontTrue_flow0'
Process Process-22:
Traceback (most recent call last):
  File "/usr/lib/python2.7/multiprocessing/process.py", line 258, in _bootstrap
    self.run()
  File "/usr/lib/python2.7/multiprocessing/process.py", line 114, in run
    self._target(*self._args, **self._kwargs)
  File "./run_sim_perflow_longest_load_exponential_lognormal_exponential_scan_8_cores.py", line 184, in run_sim
    with open(flow_name, 'w') as f:
IOError: [Errno 36] File name too long: '../../out/fall2017/perflow_queue_longest_load_exponential_lognormal_exponential_scan/sim_8_perflow_0.0_LongestLoadDequeuePolicy_flow0_exponential_request_poisson_arrival_0.326666666667_2.0_2.0_enqfrontTrue_flow1_lognormal_request_poisson_arrival_0.326666666667_20.0_200.0_2.0_enqfrontFalse_flow2_exponential_request_poisson_arrival_0.326666666667_20.0_2.0_enqfrontTrue_flow0'
Process Process-23:
Traceback (most recent call last):
  File "/usr/lib/python2.7/multiprocessing/process.py", line 258, in _bootstrap
    self.run()
  File "/usr/lib/python2.7/multiprocessing/process.py", line 114, in run
    self._target(*self._args, **self._kwargs)
  File "./run_sim_perflow_first_packet_wait_exponential_lognormal_exponential_scan_8_cores.py", line 184, in run_sim
    with open(flow_name, 'w') as f:
IOError: [Errno 36] File name too long: '../../out/fall2017/perflow_queue_first_packet_wait_exponential_lognormal_exponential_scan/sim_8_perflow_0.0_FirstPacketWaitDequeuePolicy_flow0_exponential_request_poisson_arrival_0.33_2.0_2.0_enqfrontTrue_flow1_lognormal_request_poisson_arrival_0.33_20.0_200.0_2.0_enqfrontFalse_flow2_exponential_request_poisson_arrival_0.33_20.0_2.0_enqfrontTrue_flow0'
Winding down
Process Process-23:
Traceback (most recent call last):
  File "/usr/lib/python2.7/multiprocessing/process.py", line 258, in _bootstrap
    self.run()
  File "/usr/lib/python2.7/multiprocessing/process.py", line 114, in run
    self._target(*self._args, **self._kwargs)
  File "./run_sim_perflow_longest_load_exponential_lognormal_exponential_scan_8_cores.py", line 184, in run_sim
    with open(flow_name, 'w') as f:
IOError: [Errno 36] File name too long: '../../out/fall2017/perflow_queue_longest_load_exponential_lognormal_exponential_scan/sim_8_perflow_0.0_LongestLoadDequeuePolicy_flow0_exponential_request_poisson_arrival_0.33_2.0_2.0_enqfrontTrue_flow1_lognormal_request_poisson_arrival_0.33_20.0_200.0_2.0_enqfrontFalse_flow2_exponential_request_poisson_arrival_0.33_20.0_2.0_enqfrontTrue_flow0'
Winding down
Process Process-23:
Traceback (most recent call last):
  File "/usr/lib/python2.7/multiprocessing/process.py", line 258, in _bootstrap
    self.run()
  File "/usr/lib/python2.7/multiprocessing/process.py", line 114, in run
    self._target(*self._args, **self._kwargs)
  File "./run_sim_perflow_first_packet_slo_exponential_lognormal_exponential_scan_8_cores.py", line 184, in run_sim
    with open(flow_name, 'w') as f:
IOError: [Errno 36] File name too long: '../../out/fall2017/perflow_queue_first_packet_slo_exponential_lognormal_exponential_scan/sim_8_perflow_0.0_FirstPacketLatencyDequeuePolicy_flow0_exponential_request_poisson_arrival_0.33_2.0_2.0_enqfrontTrue_flow1_lognormal_request_poisson_arrival_0.33_20.0_200.0_2.0_enqfrontFalse_flow2_exponential_request_poisson_arrival_0.33_20.0_2.0_enqfrontTrue_flow0'
Winding down
Winding down
Winding down
Winding down
Winding down
Winding down
Winding down
Winding down
Winding down
Winding down
Winding down
Winding down
Winding down
Winding down
Winding down
Winding down
Winding down
Winding down
Winding down
Winding down
Winding down
